Workbook

Sheet 00_Tong_Quan
A1: TỔNG QUAN THỰC THI KIỂM THỬ THỦ CÔNG BACKEND
A3: Tổng quan
A4: Tổng số test case | B4: =SUM(COUNTA('01_API_Chuc_Nang'!$A:$A)-1,COUNTA('02_Xac_Thuc_Phan_Quyen'!$A:$A)-1,COUNTA('03_Luong_Nghiep_Vu'!$A:$A)-1,COUNTA('04_Chuyen_Trang_Thai'!$A:$A)-1,COUNTA('05_Du_Lieu'!$A:$A)-1,COUNTA('06_Tich_Hop'!$A:$A)-1,COUNTA('07_Bao_Mat'!$A:$A)-1,COUNTA('08_Dong_Thoi'!$A:$A)-1,COUNTA('09_Kha_Nang_Phu_Hoi'!$A:$A)-1,COUNTA('10_Hieu_Nang'!$A:$A)-1) -> 76
A5: PASS | B5: =SUM(COUNTIF('01_API_Chuc_Nang'!$L:$L,"PASS"),COUNTIF('02_Xac_Thuc_Phan_Quyen'!$L:$L,"PASS"),COUNTIF('03_Luong_Nghiep_Vu'!$L:$L,"PASS"),COUNTIF('04_Chuyen_Trang_Thai'!$L:$L,"PASS"),COUNTIF('05_Du_Lieu'!$L:$L,"PASS"),COUNTIF('06_Tich_Hop'!$L:$L,"PASS"),COUNTIF('07_Bao_Mat'!$L:$L,"PASS"),COUNTIF('08_Dong_Thoi'!$L:$L,"PASS"),COUNTIF('09_Kha_Nang_Phu_Hoi'!$L:$L,"PASS"),COUNTIF('10_Hieu_Nang'!$L:$L,"PASS")) -> 66
A6: FAIL | B6: =SUM(COUNTIF('01_API_Chuc_Nang'!$L:$L,"FAIL"),COUNTIF('02_Xac_Thuc_Phan_Quyen'!$L:$L,"FAIL"),COUNTIF('03_Luong_Nghiep_Vu'!$L:$L,"FAIL"),COUNTIF('04_Chuyen_Trang_Thai'!$L:$L,"FAIL"),COUNTIF('05_Du_Lieu'!$L:$L,"FAIL"),COUNTIF('06_Tich_Hop'!$L:$L,"FAIL"),COUNTIF('07_Bao_Mat'!$L:$L,"FAIL"),COUNTIF('08_Dong_Thoi'!$L:$L,"FAIL"),COUNTIF('09_Kha_Nang_Phu_Hoi'!$L:$L,"FAIL"),COUNTIF('10_Hieu_Nang'!$L:$L,"FAIL")) -> 5
A7: BLOCKED | B7: =SUM(COUNTIF('01_API_Chuc_Nang'!$L:$L,"BLOCKED"),COUNTIF('02_Xac_Thuc_Phan_Quyen'!$L:$L,"BLOCKED"),COUNTIF('03_Luong_Nghiep_Vu'!$L:$L,"BLOCKED"),COUNTIF('04_Chuyen_Trang_Thai'!$L:$L,"BLOCKED"),COUNTIF('05_Du_Lieu'!$L:$L,"BLOCKED"),COUNTIF('06_Tich_Hop'!$L:$L,"BLOCKED"),COUNTIF('07_Bao_Mat'!$L:$L,"BLOCKED"),COUNTIF('08_Dong_Thoi'!$L:$L,"BLOCKED"),COUNTIF('09_Kha_Nang_Phu_Hoi'!$L:$L,"BLOCKED"),COUNTIF('10_Hieu_Nang'!$L:$L,"BLOCKED")) -> 5
A8: NOT RUN | B8: =SUM(COUNTIF('01_API_Chuc_Nang'!$L:$L,"NOT RUN"),COUNTIF('02_Xac_Thuc_Phan_Quyen'!$L:$L,"NOT RUN"),COUNTIF('03_Luong_Nghiep_Vu'!$L:$L,"NOT RUN"),COUNTIF('04_Chuyen_Trang_Thai'!$L:$L,"NOT RUN"),COUNTIF('05_Du_Lieu'!$L:$L,"NOT RUN"),COUNTIF('06_Tich_Hop'!$L:$L,"NOT RUN"),COUNTIF('07_Bao_Mat'!$L:$L,"NOT RUN"),COUNTIF('08_Dong_Thoi'!$L:$L,"NOT RUN"),COUNTIF('09_Kha_Nang_Phu_Hoi'!$L:$L,"NOT RUN"),COUNTIF('10_Hieu_Nang'!$L:$L,"NOT RUN")) -> 0
A9: Tỷ lệ đạt | B9: =IF(B4=0,0,B5/B4) -> 0.86842105
A11: Mức ưu tiên
A12: P0 | B12: =SUM(COUNTIF('01_API_Chuc_Nang'!$E:$E,"P0"),COUNTIF('02_Xac_Thuc_Phan_Quyen'!$E:$E,"P0"),COUNTIF('03_Luong_Nghiep_Vu'!$E:$E,"P0"),COUNTIF('04_Chuyen_Trang_Thai'!$E:$E,"P0"),COUNTIF('05_Du_Lieu'!$E:$E,"P0"),COUNTIF('06_Tich_Hop'!$E:$E,"P0"),COUNTIF('07_Bao_Mat'!$E:$E,"P0"),COUNTIF('08_Dong_Thoi'!$E:$E,"P0"),COUNTIF('09_Kha_Nang_Phu_Hoi'!$E:$E,"P0"),COUNTIF('10_Hieu_Nang'!$E:$E,"P0")) -> 34
A13: P1 | B13: =SUM(COUNTIF('01_API_Chuc_Nang'!$E:$E,"P1"),COUNTIF('02_Xac_Thuc_Phan_Quyen'!$E:$E,"P1"),COUNTIF('03_Luong_Nghiep_Vu'!$E:$E,"P1"),COUNTIF('04_Chuyen_Trang_Thai'!$E:$E,"P1"),COUNTIF('05_Du_Lieu'!$E:$E,"P1"),COUNTIF('06_Tich_Hop'!$E:$E,"P1"),COUNTIF('07_Bao_Mat'!$E:$E,"P1"),COUNTIF('08_Dong_Thoi'!$E:$E,"P1"),COUNTIF('09_Kha_Nang_Phu_Hoi'!$E:$E,"P1"),COUNTIF('10_Hieu_Nang'!$E:$E,"P1")) -> 39
A14: P2 | B14: =SUM(COUNTIF('01_API_Chuc_Nang'!$E:$E,"P2"),COUNTIF('02_Xac_Thuc_Phan_Quyen'!$E:$E,"P2"),COUNTIF('03_Luong_Nghiep_Vu'!$E:$E,"P2"),COUNTIF('04_Chuyen_Trang_Thai'!$E:$E,"P2"),COUNTIF('05_Du_Lieu'!$E:$E,"P2"),COUNTIF('06_Tich_Hop'!$E:$E,"P2"),COUNTIF('07_Bao_Mat'!$E:$E,"P2"),COUNTIF('08_Dong_Thoi'!$E:$E,"P2"),COUNTIF('09_Kha_Nang_Phu_Hoi'!$E:$E,"P2"),COUNTIF('10_Hieu_Nang'!$E:$E,"P2")) -> 3
A16: Nhóm kiểm thử | B16: Tổng | C16: PASS | D16: FAIL | E16: BLOCKED | F16: NOT RUN | G16: Tỷ lệ đạt
A17: API chức năng | B17: =COUNTA('01_API_Chuc_Nang'!$A:$A)-1 -> 21 | C17: =COUNTIF('01_API_Chuc_Nang'!$L:$L,"PASS") -> 21 | D17: =COUNTIF('01_API_Chuc_Nang'!$L:$L,"FAIL") -> 0 | E17: =COUNTIF('01_API_Chuc_Nang'!$L:$L,"BLOCKED") -> 0 | F17: =COUNTIF('01_API_Chuc_Nang'!$L:$L,"NOT RUN") -> 0 | G17: =IF(B17=0,0,C17/B17) -> 1
A18: Xác thực & phân quyền | B18: =COUNTA('02_Xac_Thuc_Phan_Quyen'!$A:$A)-1 -> 7 | C18: =COUNTIF('02_Xac_Thuc_Phan_Quyen'!$L:$L,"PASS") -> 7 | D18: =COUNTIF('02_Xac_Thuc_Phan_Quyen'!$L:$L,"FAIL") -> 0 | E18: =COUNTIF('02_Xac_Thuc_Phan_Quyen'!$L:$L,"BLOCKED") -> 0 | F18: =COUNTIF('02_Xac_Thuc_Phan_Quyen'!$L:$L,"NOT RUN") -> 0 | G18: =IF(B18=0,0,C18/B18) -> 1
A19: Luồng nghiệp vụ | B19: =COUNTA('03_Luong_Nghiep_Vu'!$A:$A)-1 -> 8 | C19: =COUNTIF('03_Luong_Nghiep_Vu'!$L:$L,"PASS") -> 7 | D19: =COUNTIF('03_Luong_Nghiep_Vu'!$L:$L,"FAIL") -> 1 | E19: =COUNTIF('03_Luong_Nghiep_Vu'!$L:$L,"BLOCKED") -> 0 | F19: =COUNTIF('03_Luong_Nghiep_Vu'!$L:$L,"NOT RUN") -> 0 | G19: =IF(B19=0,0,C19/B19) -> 0.875
A20: Chuyển trạng thái | B20: =COUNTA('04_Chuyen_Trang_Thai'!$A:$A)-1 -> 11 | C20: =COUNTIF('04_Chuyen_Trang_Thai'!$L:$L,"PASS") -> 9 | D20: =COUNTIF('04_Chuyen_Trang_Thai'!$L:$L,"FAIL") -> 2 | E20: =COUNTIF('04_Chuyen_Trang_Thai'!$L:$L,"BLOCKED") -> 0 | F20: =COUNTIF('04_Chuyen_Trang_Thai'!$L:$L,"NOT RUN") -> 0 | G20: =IF(B20=0,0,C20/B20) -> 0.81818182
A21: Cơ sở dữ liệu | B21: =COUNTA('05_Du_Lieu'!$A:$A)-1 -> 4 | C21: =COUNTIF('05_Du_Lieu'!$L:$L,"PASS") -> 4 | D21: =COUNTIF('05_Du_Lieu'!$L:$L,"FAIL") -> 0 | E21: =COUNTIF('05_Du_Lieu'!$L:$L,"BLOCKED") -> 0 | F21: =COUNTIF('05_Du_Lieu'!$L:$L,"NOT RUN") -> 0 | G21: =IF(B21=0,0,C21/B21) -> 1
A22: Tích hợp | B22: =COUNTA('06_Tich_Hop'!$A:$A)-1 -> 5 | C22: =COUNTIF('06_Tich_Hop'!$L:$L,"PASS") -> 3 | D22: =COUNTIF('06_Tich_Hop'!$L:$L,"FAIL") -> 2 | E22: =COUNTIF('06_Tich_Hop'!$L:$L,"BLOCKED") -> 0 | F22: =COUNTIF('06_Tich_Hop'!$L:$L,"NOT RUN") -> 0 | G22: =IF(B22=0,0,C22/B22) -> 0.6
A23: Bảo mật | B23: =COUNTA('07_Bao_Mat'!$A:$A)-1 -> 6 | C23: =COUNTIF('07_Bao_Mat'!$L:$L,"PASS") -> 6 | D23: =COUNTIF('07_Bao_Mat'!$L:$L,"FAIL") -> 0 | E23: =COUNTIF('07_Bao_Mat'!$L:$L,"BLOCKED") -> 0 | F23: =COUNTIF('07_Bao_Mat'!$L:$L,"NOT RUN") -> 0 | G23: =IF(B23=0,0,C23/B23) -> 1
A24: Đồng thời | B24: =COUNTA('08_Dong_Thoi'!$A:$A)-1 -> 6 | C24: =COUNTIF('08_Dong_Thoi'!$L:$L,"PASS") -> 6 | D24: =COUNTIF('08_Dong_Thoi'!$L:$L,"FAIL") -> 0 | E24: =COUNTIF('08_Dong_Thoi'!$L:$L,"BLOCKED") -> 0 | F24: =COUNTIF('08_Dong_Thoi'!$L:$L,"NOT RUN") -> 0 | G24: =IF(B24=0,0,C24/B24) -> 1
A25: Khả năng phục hồi | B25: =COUNTA('09_Kha_Nang_Phu_Hoi'!$A:$A)-1 -> 3 | C25: =COUNTIF('09_Kha_Nang_Phu_Hoi'!$L:$L,"PASS") -> 3 | D25: =COUNTIF('09_Kha_Nang_Phu_Hoi'!$L:$L,"FAIL") -> 0 | E25: =COUNTIF('09_Kha_Nang_Phu_Hoi'!$L:$L,"BLOCKED") -> 0 | F25: =COUNTIF('09_Kha_Nang_Phu_Hoi'!$L:$L,"NOT RUN") -> 0 | G25: =IF(B25=0,0,C25/B25) -> 1
A26: Hiệu năng | B26: =COUNTA('10_Hieu_Nang'!$A:$A)-1 -> 5 | C26: =COUNTIF('10_Hieu_Nang'!$L:$L,"PASS") -> 0 | D26: =COUNTIF('10_Hieu_Nang'!$L:$L,"FAIL") -> 0 | E26: =COUNTIF('10_Hieu_Nang'!$L:$L,"BLOCKED") -> 5 | F26: =COUNTIF('10_Hieu_Nang'!$L:$L,"NOT RUN") -> 0 | G26: =IF(B26=0,0,C26/B26) -> 0

Sheet 01_API_Chuc_Nang
A1: Mã test case | B1: Nhóm | C1: API | D1: Kịch bản | E1: Ưu tiên | F1: Điều kiện trước | G1: Dữ liệu test | H1: Các bước test | I1: Status mong đợi | J1: Kết quả mong đợi | K1: Kết quả thực tế | L1: Trạng thái | M1: Bug / Ghi chú
A2: TC-CATALOG-001 | B2: 01 API chức năng | C2: GET /api/v1/catalog/locations | D2: Lấy danh mục vị trí | E2: P2 | F2: Đã có dữ liệu seed danh mục | G2: Vai trò: RESIDENT | H2: 1. GET /api/v1/catalog/locations; 2. Kiểm tra cấu trúc danh sách | I2: 200 | J2: Phản hồi: data là mảng; mỗi item có id/name/type các field client cần | K2: HTTP 200. Response trả về danh sách vị trí hợp lệ; mỗi item có id, label, tầng, loại vị trí và unit_code nếu là vị trí trong căn hộ. Không có lỗi trong response. | L2: PASS
A3: TC-CATALOG-003 | B3: 01 API chức năng | C3: GET /api/v1/catalog/categories | D3: Lấy danh mục phản ánh đang hoạt động | E3: P2 | F3: Category seed exists | G3: Vai trò: RESIDENT | H3: 1. GET /api/v1/catalog/categories; 2. Kiểm tra dữ liệu category đang hoạt động | I3: 200 | J3: Phản hồi: data là mảng; category id/code/display_name tồn tại | K3: HTTP 200. Response trả về danh sách danh mục phản ánh đang hoạt động; mỗi item có id, code và display_name. Không có lỗi trong response. | L3: PASS
A4: TC-STORAGE-001 | B4: 01 API chức năng | C4: POST /api/v1/storage/ticket-attachments/upload-url | D4: Tạo signed upload URL cho ảnh phản ánh | E4: P1 | F4: Cư dân đang active | G4: Vai trò: RESIDENT | Body: {"original_filename":"incident-test.jpg","mime_type":"image/jpeg","file_size":245760} | H4: 1. POST upload-url; 2. Gửi body; 3. Lưu upload_id và signed URL | I4: 201 | J4: Phản hồi: data.upload_id and signed upload URL tồn tại | Cơ sở dữ liệu: ticket_attachment_upload_sessions row được tạo with owner cư dân and status pending | Tác động phụ: Supabase Storage signed URL được yêu cầu | K4: HTTP 201. Backend tạo upload_id và signed upload URL cho ảnh phản ánh. DB ghi nhận upload session trạng thái pending, đúng owner là cư dân hiện tại. | L4: PASS
A5: TC-STORAGE-003 | B5: 01 API chức năng | C5: POST /api/v1/storage/completion-evidence/upload-url | D5: Tạo signed upload URL cho bằng chứng hoàn thành | E5: P1 | F5: KTV đang active | G5: Vai trò: TECHNICIAN | Body: {"original_filename":"done.jpg","mime_type":"image/jpeg","file_size":200000} | H5: 1. POST completion upload-url; 2. Gửi body; 3. Lưu upload_id | I5: 201 | J5: Phản hồi: data.upload_id and signed upload URL tồn tại | Cơ sở dữ liệu: completion upload session được tạo for KTV | Tác động phụ: Supabase Storage signed URL được yêu cầu | K5: HTTP 201. Backend tạo upload_id và signed upload URL cho ảnh bằng chứng hoàn thành. Upload session gắn với KTV hiện tại và ở trạng thái pending. | L5: PASS
A6: TC-TICKET-001 | B6: 01 API chức năng | C6: POST /api/v1/tickets | D6: Tạo phản ánh chỉ có mô tả | E6: P0 | F6: Cư dân đang đang hoạt động và đã được liên kết; location tồn tại | G6: Vai trò: RESIDENT | Body: {"location_id":"{{LOCATION_ID}}","description":"Vòi nước rò rỉ ở hành lang tầng 7","attachment_upload_ids":[]} | H6: 1. POST /api/v1/tickets; 2. Gửi body hợp lệ; 3. Lưu ticket_id | I6: 202 | J6: Phản hồi: data.ticket_id or ticket data returned; error là null; request_id tồn tại | Cơ sở dữ liệu: tickets row được tạo with reporter cư dân; analysis background task scheduled | Tác động phụ: Tác vụ phân tích AI nền được đưa vào hàng đợi | K6: HTTP 202. Backend tạo ticket chỉ có mô tả, trả về ticket_id và trạng thái xử lý ban đầu. DB có ticket mới và background analysis/agent được kích hoạt. | L6: PASS
A7: TC-TICKET-002 | B7: 01 API chức năng | C7: POST /api/v1/tickets | D7: Tạo phản ánh với ảnh đã upload hợp lệ | E7: P0 | F7: Cư dân có upload_id pending hợp lệ; object trên storage đã được xác minh | G7: Vai trò: RESIDENT | Body: {"location_id":"{{LOCATION_ID}}","description":"Có khói ở khu vực bếp","attachment_upload_ids":["{{UPLOAD_ID}}"]} | H7: 1. Tạo upload URL; 2. Tải ảnh test lên; 3. POST ticket; 4. Kiểm tra attachment | I7: 202 | J7: Phản hồi: Ticket được tạo; attachment linked in response if exposed | Cơ sở dữ liệu: tạo dòng ticket; upload session consumed; ticket_attachments row được tạo | Tác động phụ: Phân tích AI được đưa vào hàng đợi | K7: HTTP 202. Ticket được tạo với ảnh đã upload hợp lệ. Upload session được consume, ticket_attachments được tạo và analysis/agent được kích hoạt. | L7: PASS
A8: TC-TICKET-008 | B8: 01 API chức năng | C8: GET /api/v1/tickets | D8: Liệt kê phản ánh resident được phép xem | E8: P1 | F8: Cư dân có ticket của chính mình và cùng unit | G8: Vai trò: RESIDENT | H8: 1. GET /api/v1/tickets; 2. Kiểm tra list chỉ chứa các phản ánh được phép xem | I8: 200 | J8: Phản hồi: data là mảng/list envelope; không rò rỉ dữ liệu riêng chỉ dành cho AI | K8: HTTP 200. Resident chỉ xem được các phản ánh thuộc phạm vi được phép; response có items, page, page_size, total và không lộ dữ liệu ngoài quyền. | L8: PASS
A9: TC-TICKET-009 | B9: 01 API chức năng | C9: GET /api/v1/tickets/{ticket_id} | D9: Xem chi tiết phản ánh của chính mình | E9: P1 | F9: Ticket belongs to cư dân or visible unit | G9: Vai trò: RESIDENT | Tham số đường dẫn: ticket_id={{TICKET_ID}} | H9: 1. GET endpoint chi tiết; 2. Kiểm tra cấu trúc status/category/attachments trong body | I9: 200 | J9: Phản hồi: data.id={{TICKET_ID}}; error là null | K9: HTTP 200. Resident xem được chi tiết ticket của chính mình; response có thông tin trạng thái, vị trí, mô tả, timeline, attachment nếu có và error=null. | L9: PASS
A10: TC-TICKET-011 | B10: 01 API chức năng | C10: POST /api/v1/tickets/{ticket_id}/cancel | D10: Hủy phản ánh NEW của chính mình | E10: P1 | F10: Ticket có trạng thái NEW; người thao tác là người báo cáo; không có emergency gate đang chờ | G10: Vai trò: RESIDENT | Tham số đường dẫn: ticket_id={{NEW_TICKET_ID}} | H10: 1. POST cancel; 2. Kiểm tra trạng thái đã hủy | I10: 200 | J10: Phản hồi: data.status indicates canceled; error là null | Cơ sở dữ liệu: Ticket status được cập nhật to canceled; status history/audit nếu đã triển khai | Tác động phụ: Thông báo nếu đã triển khai | K10: HTTP 200. Resident hủy được ticket còn NEW do chính mình tạo. DB cập nhật trạng thái ticket sang CANCELLED và ghi nhận lịch sử trạng thái tương ứng. | L10: PASS
A11: TC-AGENTQ-001 | B11: 01 API chức năng | C11: GET /api/v1/tickets/{ticket_id}/agent-question | D11: Lấy câu hỏi bổ sung đang chờ từ agent | E11: P1 | F11: Ticket có câu hỏi từ agent chưa được cư dân trả lời | G11: Vai trò: RESIDENT | Tham số đường dẫn: ticket_id={{QUESTION_TICKET_ID}} | H11: 1. GET agent-question; 2. Kiểm tra các trường/tùy chọn của câu hỏi | I11: 200 | J11: Phản hồi: data.question_id tồn tại; trạng thái câu hỏi là pending | K11: HTTP 200. Khi agent cần bổ sung thông tin, endpoint trả về câu hỏi pending gồm id, question_kind, question_type, options nếu có và thời hạn trả lời. | L11: PASS
A12: TC-AGENTQ-003 | B12: 01 API chức năng | C12: POST /api/v1/tickets/{ticket_id}/agent-question/{question_id}/answer | D12: Trả lời câu hỏi agent bằng văn bản | E12: P0 | F12: Có câu hỏi pending và thuộc ticket của cư dân | G12: Vai trò: RESIDENT | Tham số đường dẫn: ticket_id={{QUESTION_TICKET_ID}}; question_id={{QUESTION_ID}} | Body: {"answer_type":"FREE_TEXT","answer_text":"Vị trí chính xác là hành lang tầng 7, gần thang máy","upload_id":null,"selected_location_id":null} | H12: 1. POST answer endpoint; 2. Gửi body; 3. Kiểm tra câu hỏi đã được trả lời | I12: 200 | J12: Phản hồi: data indicates answer accepted; error là null | Cơ sở dữ liệu: AIAgentQuestion answer fields được cập nhật; quá trình phân tích tiếp tục nếu áp dụng | Tác động phụ: AI analysis có thể được đưa vào hàng đợi | K12: HTTP 200. Resident trả lời câu hỏi agent hợp lệ. DB cập nhật question thành ANSWERED, lưu answer_text/answer_payload và cho phép analysis tiếp tục. | L12: PASS
A13: TC-COORD-001 | B13: 01 API chức năng | C13: GET /api/v1/coordinator/tickets | D13: BQL xem danh sách phản ánh | E13: P1 | F13: BQL đang active; đã seed dữ liệu ticket | G13: Vai trò: COORDINATOR | H13: 1. GET BQL tickets; 2. Kiểm tra danh sách và các trường trạng thái | I13: 200 | J13: Phản hồi: data là danh sách/trang; các dòng ticket hiển thị cho BQL | K13: HTTP 200. BQL xem được danh sách phản ánh; response có items và phân trang, bao gồm trạng thái phân loại, ưu tiên, điểm rủi ro và thông tin gán việc nếu có. | L13: PASS
... A22: TC-ACCOUNT-007 | B22: 01 API chức năng | C22: POST /api/v1/coordinator/accounts/technicians | D22: Tạo tài khoản KTV | E22: P1 | F22: BQL đang active; category kỹ năng tồn tại; email chưa được sử dụng | G22: Vai trò: COORDINATOR | Body: {"email":"ktv.new@homecare.local","password":"HomeCareTest2026","full_name":"KTV New","phone_number":"+84900000021","skill_category_ids":["{{CATEGORY_ID}}"],"is_available":true} | H22: 1. POST tạo KTV; 2. Kiểm tra hồ sơ và kỹ năng | I22: 201 | J22: Phản hồi: data chứa tài khoản KTV | Cơ sở dữ liệu: Tạo Auth user/profile/KTV_profile/skills | Tác động phụ: Tạo audit log | K22: HTTP 201. BQL tạo được tài khoản KTV. Supabase Auth, user_profiles, technician_profiles và skills được tạo đúng dữ liệu; tài khoản active/available theo request. | L22: PASS

Sheet 02_Xac_Thuc_Phan_Quyen
A1: Mã test case | B1: Nhóm | C1: API | D1: Kịch bản | E1: Ưu tiên | F1: Điều kiện trước | G1: Dữ liệu test | H1: Các bước test | I1: Status mong đợi | J1: Kết quả mong đợi | K1: Kết quả thực tế | L1: Trạng thái | M1: Bug / Ghi chú
A2: TC-AUTH-006 | B2: 02 Xác thực & phân quyền | C2: GET /api/v1/me | D2: Lấy hồ sơ hiện tại bằng token resident hợp lệ | E2: P0 | F2: Cư dân profile exists and active | G2: Vai trò: RESIDENT | H2: 1. GET {{BASE_URL}}/api/v1/me; 2. Thêm token cư dân; 3. Gửi | I2: 200 | J2: Phản hồi: data.role=RESIDENT; data.user_id tồn tại; error là null | K2: HTTP 200. /me trả role=RESIDENT, is_active=True; response không có password hay token nội bộ. | L2: PASS
A3: TC-AUTH-007 | B3: 02 Xác thực & phân quyền | C3: GET /api/v1/me | D3: Từ chối request chưa được xác thực qua middleware auth chung | E3: P0 | F3: Backend đang chạy | G3: Vai trò: Công khai | Header: Không có header Authorization | H3: 1. GET /api/v1/me không có Authorization; 2. Gửi; 3. Kiểm tra lỗi | I3: 401 | J3: Phản hồi: error.code=AUTH_REQUIRED | K3: HTTP 401. Request không có Authorization bị từ chối; error.code=AUTH_REQUIRED. | L3: PASS
A4: TC-AUTH-008 | B4: 02 Xác thực & phân quyền | C4: GET /api/v1/me | D4: Từ chối user đang bị khóa | E4: P0 | F4: Hồ sơ user có is_active=false | G4: Vai trò: RESIDENT | H4: 1. GET /api/v1/me với token của user bị khóa; 2. Gửi | I4: 403 | J4: Phản hồi: error.code=USER_INACTIVE | K4: Khóa tài khoản HTTP 200; token cũ gọi /me HTTP 403 và /tickets HTTP 403, cùng error.code=USER_INACTIVE. Khôi phục tài khoản HTTP 200. | L4: PASS
A5: TC-SEC-011 | B5: 02 Xác thực & phân quyền | C5: GET /api/v1/coordinator/tickets | D5: Từ chối JWT bị sửa hoặc giả mạo ở endpoint BQL | E5: P0 | F5: Backend đang chạy; tạo JWT không hợp lệ bằng cách sửa một ký tự trong token hợp lệ | G5: Header: Authorization=Bearer {{TAMPERED_TOKEN}} | H5: 1. GET BQL tickets với token đã bị sửa; 2. Kiểm tra response; 3. Xác nhận no audit/business side effect | I5: 401 | J5: Phản hồi HTTP: error.code=AUTH_TOKEN_INVALID or AUTH_REQUIRED. Cơ sở dữ liệu: không có thay đổi dữ liệu phía đọc hoặc audit cho thấy actor hợp lệ. | K5: JWT bị sửa trên endpoint coordinator trả về HTTP 401; error.code=AUTH_TOKEN_INVALID. | L5: PASS
A6: TC-SEC-012 | B6: 02 Xác thực & phân quyền | C6: GET /api/v1/me | D6: Từ chối JWT hết hạn | E6: P1 | F6: Có token test hết hạn từ thiết lập auth test; không giả lập bằng cách thay đổi đồng hồ hệ thống toàn cục | G6: Header: Authorization=Bearer {{EXPIRED_TOKEN}} | H6: 1. GET /api/v1/me với token hết hạn; 2. Kiểm tra response | I6: 401 | J6: Phản hồi HTTP: error.code=AUTH_TOKEN_EXPIRED or AUTH_TOKEN_INVALID. Cơ sở dữ liệu: không cập nhật hồ sơ. | K6: GET /me với JWT ký hợp lệ nhưng hết hạn trả HTTP 401, code=AUTH_TOKEN_EXPIRED; user profile không thay đổi=True. | L6: PASS
A7: TC-COORD-002 | B7: 02 Xác thực & phân quyền | C7: GET /api/v1/coordinator/tickets | D7: Từ chối sai role qua authorization coordinator chung | E7: P0 | F7: Cư dân đang active | G7: Vai trò: RESIDENT | H7: 1. GET BQL tickets with cư dân token; 2. Kiểm tra bị từ chối quyền | I7: 403 | J7: Phản hồi: error.code=FORBIDDEN | K7: Token resident trên endpoint coordinator trả về HTTP 403; error.code=FORBIDDEN. | L7: PASS
A8: TC-STORAGE-004 | B8: 02 Xác thực & phân quyền | C8: POST /api/v1/storage/completion-evidence/upload-url | D8: Từ chối resident tạo upload URL bằng chứng hoàn thành | E8: P1 | F8: Cư dân đang active | G8: Vai trò: RESIDENT | Body: {"original_filename":"done.jpg","mime_type":"image/jpeg","file_size":200000} | H8: 1. POST KTV storage endpoint with cư dân token; 2. Kiểm tra bị từ chối quyền | I8: 403 | J8: Phản hồi: error.code=FORBIDDEN | Cơ sở dữ liệu: Không tạo upload session | Tác động phụ: Không tạo signed URL | K8: Token resident trên endpoint storage của technician trả về HTTP 403; error.code=FORBIDDEN; upload_session_count 2->2. | L8: PASS

Sheet 03_Luong_Nghiep_Vu
A1: Mã test case | B1: Nhóm | C1: API | D1: Kịch bản | E1: Ưu tiên | F1: Điều kiện trước | G1: Dữ liệu test | H1: Các bước test | I1: Status mong đợi | J1: Kết quả mong đợi | K1: Kết quả thực tế | L1: Trạng thái | M1: Bug / Ghi chú
A2: TC-FLOW-001 | B2: 03 Luồng nghiệp vụ | C2: MULTI-API | D2: Cư dân tạo phản ánh, BQL phân công, KTV hoàn thành | E2: P0 | F2: Cư dân, BQL, KTV, category, location, storage đều đã được chuẩn bị | G2: Vai trò: Nhiều vai trò | Header: Dùng token theo vai trò ở từng bước | Body: Xem body của từng bước | H2: 1. Run TC-STORAGE-001 if image; 2. Run TC-TICKET-001/002; 3. Hoàn thành AI analysis; 4. Run TC-COORD-004; 5. Run TC-COORD phân công/TC-VISUAL-004; 6. Run TC-TECH-007; 7. Run TC-STORAGE-003; 8. Run TC-TECH-014 | I2: All step statuses pass | J2: Phản hồi: Final ticket completed and all response bodies match each API | Cơ sở dữ liệu: Ticket completed; phân công completed; evidence saved; audit/status history correct | Tác động phụ: Cư dân/BQL/KTV notifications correct | K2: Tạo resident HTTP 201; tạo ticket HTTP 202; LLM -> classification=RESOLVED, status=APPROVED, priority=P1, manual_resolve/approve=200/200; assign/start/upload/PUT/complete=200/200/201/200/200; DB ticket=COMPLETED, assignment=COMPLETED. | L2: PASS
A3: TC-FLOW-002 | B3: 03 Luồng nghiệp vụ | C3: MULTI-API | D3: P5 đã xác nhận vẫn xử lý thủ công, không phân công | E3: P0 | F3: P5 pending ticket exists | G3: Vai trò: COORDINATOR | Tham số đường dẫn: ticket_id={{P5_PENDING_TICKET_ID}} | Body: Xem body trong TC-P5 | H3: 1. Chạy TC-P5-001; 2. Thử TC-P5-005; 3. Kiểm tra ticket bị loại khỏi visual board; 4. Chạy dispatch một lần; 5. Check no phân công | I3: 200 sau đó 409/absent as expected | J3: Phản hồi: P5 đã được xác nhận; phân công attempts bị chặn | Cơ sở dữ liệu: No ticket_phân công for P5 | Tác động phụ: Emergency notification/audit exists | K3: P5 confirmed; assign HTTP 500; visual board HTTP 200, ticket xuất hiện=False; dispatch HTTP 200; assignment_count sau dispatch=0. | L3: FAIL | M3: BUG-P5-003 - Một hoặc nhiều gate manual-only P5 chưa đúng contract.
A4: TC-FLOW-003 | B4: 03 Luồng nghiệp vụ | C4: MULTI-API | D4: Hạ P5 rồi quay lại luồng phân công thường | E4: P0 | F4: Có ticket P5 pending và BQL quyết định không phải khẩn cấp | G4: Vai trò: COORDINATOR | Tham số đường dẫn: ticket_id={{P5_PENDING_TICKET_ID}} | Body: See TC-P5-002 body | H4: 1. Chạy TC-P5-002; 2. Xử lý duplicate/grouping nếu cần; 3. Duyệt ticket; 4. Assign KTV; 5. KTV bắt đầu xử lý | I4: All step statuses pass | J4: Phản hồi: Mức ưu tiên below P5 and phân công allowed after rule completion | Cơ sở dữ liệu: Mức ưu tiên override saved; tạo phân công after approval | Tác động phụ: Audit/notification được tạo | K4: Fixture lưu audit run P5 DOWNGRADED rồi run grouping NO_MATCH/P3; assign HTTP 200; KTV start HTTP 200; DB ticket=IN_PROGRESS, assignment=IN_PROGRESS. | L4: PASS
A5: TC-FLOW-004 | B5: 03 Luồng nghiệp vụ | C5: MULTI-API | D5: Gộp phản ánh thành case rồi duyệt và phân công case | E5: P1 | F5: Nhiều vai trò similar đã seed dữ liệu ticket | G5: Vai trò: COORDINATOR | Tham số đường dẫn: case_id={{CASE_ID}} | Body: Xem các case cluster | H5: 1. Chạy xử lý duplicate/grouping; 2. GET danh sách cluster; 3. Duyệt cluster; 4. Phân công cluster; 5. Kiểm tra tất cả thành viên | I5: All step statuses pass | J5: Phản hồi: Case assigned all-or-nothing | Cơ sở dữ liệu: All member phân côngs được tạo or none on failure | Tác động phụ: KTV notification/audit | K5: GET clusters HTTP 200, case hiển thị=True; approve HTTP 200 (2/2 ticket); assign HTTP 200 (2/2 ticket); DB tạo 2 assignment cùng một KTV; audit ASSIGN_TECHNICIAN=2, notification phân công=4. | L5: PASS
A6: TC-FLOW-005 | B6: 03 Luồng nghiệp vụ | C6: MULTI-API | D6: Worker tự phân công tạo phân công | E6: P0 | F6: Duyệtd eligible tickets and active KTVs exist; in working hours; phân công-worker is running | G6: Vai trò: COORDINATOR | Body: See auto-phân công and dispatch event checks | H6: 1. GET auto thiết lập; 2. Bật và xác nhận; 3. Wait for phân công-worker cycle; 4. Kiểm tra màn hình dispatch event; 5. KTV mở hàng đợi | I6: All step statuses pass | J6: Phản hồi: Eligible ticket assigned; P5 skipped | Cơ sở dữ liệu: dispatch_events completed/deferred correctly; tạo phân công once | Tác động phụ: KTV notification/audit | K6: Worker chạy 2 pass; event=ASSIGNED, assignment_count=1, source=AUTO_AGENT, technician=fe8a1968-8941-4ec9-b86b-1729d3622e48. | L6: PASS
A7: TC-FLOW-006 | B7: 03 Luồng nghiệp vụ | C7: MULTI-API | D7: Khóa tài khoản làm user mất quyền truy cập | E7: P1 | F7: Có tài khoản test BQL và cư dân | G7: Vai trò: COORDINATOR/RESIDENT | Tham số đường dẫn: user_id={{RESIDENT_USER_ID}} | Body: {"is_active":false} | H7: 1. BQL disables cư dân; 2. Cư dân calls /me; 3. Cư dân calls /tickets; 4. Kiểm tra denied | I7: 200 sau đó 403 | J7: Phản hồi: User bị khóa nhận USER_INACTIVE | Cơ sở dữ liệu: user_profiles.is_active=false | K7: Khóa tài khoản HTTP 200; token cũ gọi /me HTTP 403 và /tickets HTTP 403, cùng error.code=USER_INACTIVE. Khôi phục tài khoản HTTP 200. | L7: PASS
A8: TC-FLOW-007 | B8: 03 Luồng nghiệp vụ | C8: MULTI-API | D8: Agent hỏi bổ sung, cư dân trả lời, ticket tiếp tục review | E8: P0 | F8: Agent tạo câu hỏi đang mở cho ticket; ticket thuộc cư dân | G8: API luồng: GET /tickets/{ticket_id}/agent-question; POST /tickets/{ticket_id}/agent-question/{question_id}/answer; BQL list/detail | H8: 1. Cư dân opens agent question; 2. Cư dân answers with valid text; 3. Wait or trigger resumed analysis; 4. BQL checks ticket state | I8: 200 | J8: Ticket leaves waiting question path and resumes classification. Cơ sở dữ liệu: question status answered; new analysis run or được cập nhật run records cư dân answer; no duplicate question remains open. | K8: Ticket 6a1d09e3-15e6-43f2-ad46-2a31ca0f2db3: câu hỏi ANSWERED=1, PENDING=0; analysis SUCCEEDED=1; classification=RESOLVED. | L8: PASS
A9: TC-FLOW-008 | B9: 03 Luồng nghiệp vụ | C9: MULTI-API | D9: KTV từ chối/không xử lý được và ticket quay lại đường xử lý phù hợp | E9: P0 | F9: Duyệtd ticket không phải P5 đã được phân công cho KTV; có KTV khác đủ điều kiện hoặc quản lý có thể phân công lại thủ công | G9: API luồng: POST /KTV/phân côngs/{id}/reject or unable-to-handle; GET /BQL/tickets/{ticket_id}; optional assign/worker | H9: 1. KTV từ chối công việc ASSIGNED hoặc đánh dấu IN_PROGRESS là không thể xử lý; 2. BQL xem ticket; 3. Reassign manually or let dispatch handle according to thiết lậps | I9: 200 | J9: Assignment becomes REJECTED or UNABLE_TO_HANDLE. Ticket status and queue state match current code: rejected ASSIGNED ticket returns to APPROVED for rephân công; unable-to-handle IN_PROGRESS ticket becomes UNRESOLVABLE unless rephân công flow says otherwise. Audit/notification exists. | K9: Reject ASSIGNED HTTP 200: assignment=REJECTED, ticket=APPROVED. Luồng thứ hai start HTTP 200, unable-to-handle HTTP 200: assignment=UNABLE_TO_HANDLE, ticket=UNRESOLVABLE. | L9: PASS

Sheet 04_Chuyen_Trang_Thai
A1: Mã test case | B1: Nhóm | C1: API | D1: Kịch bản | E1: Ưu tiên | F1: Điều kiện trước | G1: Dữ liệu test | H1: Các bước test | I1: Status mong đợi | J1: Kết quả mong đợi | K1: Kết quả thực tế | L1: Trạng thái | M1: Bug / Ghi chú
A2: TC-COORD-004 | B2: 04 Chuyển trạng thái | C2: POST /api/v1/coordinator/tickets/{ticket_id}/approve | D2: Duyệt phản ánh thường sau khi classification đã resolved | E2: P1 | F2: Ticket NEW; đã hoàn tất phân loại; đã có category và priority; không ở trạng thái P5 pending | G2: Vai trò: COORDINATOR | Tham số đường dẫn: ticket_id={{APPROVABLE_TICKET_ID}} | H2: 1. POST approve; 2. Kiểm tra trạng thái approved | I2: 200 | J2: Phản hồi: data.trạng thái approved; error là null | Cơ sở dữ liệu: Ticket status được cập nhật; status history/audit được tạo | Tác động phụ: Notification may be được tạo | K2: Ticket 810c1f91-8fd3-445a-a678-5c4c4f8975ca NEW/RESOLVED/P1 được approve HTTP 200; DB status=APPROVED; history 1->2, notification 0->1. | L2: PASS
A3: TC-COORD-005 | B3: 04 Chuyển trạng thái | C3: POST /api/v1/coordinator/tickets/{ticket_id}/approve | D3: Từ chối duyệt khi thiếu category/priority | E3: P1 | F3: Ticket NEW nhưng thiếu category hoặc priority | G3: Vai trò: COORDINATOR | Tham số đường dẫn: ticket_id={{UNCLASSIFIED_TICKET_ID}} | H3: 1. POST approve; 2. Kiểm tra conflict | I3: 409 | J3: Phản hồi: error.code=CATEGORY_REQUIRED or RISK_ASSESSMENT_REQUIRED | Cơ sở dữ liệu: Ticket không thay đổi | Tác động phụ: No notification | K3: Approve ticket thiếu category/priority trả HTTP 409, error.code=CATEGORY_REQUIRED; DB vẫn NEW, category=None, priority=None. | L3: PASS
A4: TC-COORD-007 | B4: 04 Chuyển trạng thái | C4: POST /api/v1/coordinator/tickets/{ticket_id}/manual-review/resolve | D4: Xử lý manual review | E4: P1 | F4: Ticket đang được review thủ công; category tồn tại | G4: Vai trò: COORDINATOR | Tham số đường dẫn: ticket_id={{MANUAL_REVIEW_TICKET_ID}} | Body: {"category_id":"{{CATEGORY_ID}}","resolution_source":"COORDINATOR","criteria":{"severity":2,"safety":1,"spread":1,"downtime":1,"customer_impact":1},"blockers":[],"evidence":null,"reason":"Đã kiểm tra nội dung và ảnh phản ánh"} | H4: 1. POST xử lý manual-review; 2. Kiểm tra phân loại ticket đã được xử lý | I4: 200 | J4: Phản hồi: data contains resolved category/priority | Cơ sở dữ liệu: Human review/risk assessment saved; ticket state được cập nhật | Tác động phụ: Audit/notification nếu đã triển khai | K4: Payload nguyên văn trong workbook trả HTTP 422 thay vì 200 do resolution_source=COORDINATOR và criteria dùng field cũ severity/safety/spread/downtime/customer_impact. Payload theo schema hiện tại (resolution_source=OTHER, 5 tiêu chí risk-v2) trả HTTP 200; DB classification=RESOLVED, priority=P2. | L4: FAIL | M4: TEST-DATA-001 - Dữ liệu TC-COORD-007 trong workbook đã lỗi thời so với API schema hiện tại; backend hoạt động với payload hiện hành.
A5: TC-COORD-008 | B5: 04 Chuyển trạng thái | C5: POST /api/v1/coordinator/tickets/{ticket_id}/manual-review/reject | D5: Từ chối phản ánh ở manual review | E5: P1 | F5: Ticket is in manual review | G5: Vai trò: COORDINATOR | Tham số đường dẫn: ticket_id={{MANUAL_REVIEW_TICKET_ID}} | Body: {"reason":"Nội dung không đủ căn cứ để tạo phản ánh"} | H5: 1. POST từ chối manual-review; 2. Kiểm tra trạng thái rejected | I5: 200 | J5: Phản hồi: data status/review state indicates rejected | Cơ sở dữ liệu: Ticket/review được cập nhật with reason | Tác động phụ: Cư dân notification nếu đã triển khai | K5: Reject manual review HTTP 200; DB status=INVALID, classification=FAILED, invalid_reason=COORDINATOR_REJECTED. | L5: PASS
A6: TC-P5-001 | B6: 04 Chuyển trạng thái | C6: POST /api/v1/coordinator/tickets/{ticket_id}/emergency-review | D6: Xác nhận phản ánh khẩn cấp P5 | E6: P0 | F6: Lần phân tích gần nhất của ticket có emergency_review_status=PENDING | G6: Vai trò: COORDINATOR | Tham số đường dẫn: ticket_id={{P5_PENDING_TICKET_ID}} | Body: {"decision":"CONFIRM_P5","priority":null,"reason":""} | H6: 1. POST emergency-review; 2. Kiểm tra P5 đã được xác nhận; 3. Kiểm tra no phân công unlocked | I6: 200 | J6: Phản hồi: data priority/status shows P5 đã được xác nhận; error là null | Cơ sở dữ liệu: AIAnalysisRun emergency status confirmed; ticket stays manual emergency path | Tác động phụ: Emergency notification/audit được tạo | K6: Ticket 42500713-ae34-4dc2-a92d-9e292dbc9231 được LLM phân tích P5/PENDING. Emergency review HTTP 200; DB priority=P5, review=CONFIRMED, decision=CONFIRM_P5, assignment_count=0. | L6: PASS
A7: TC-P5-002 | B7: 04 Chuyển trạng thái | C7: POST /api/v1/coordinator/tickets/{ticket_id}/emergency-review | D7: Hạ P5 xuống mức không khẩn cấp P1-P4 | E7: P0 | F7: Ticket has P5 review pending | G7: Vai trò: COORDINATOR | Tham số đường dẫn: ticket_id={{P5_PENDING_TICKET_ID}} | Body: {"decision":"DOWNGRADE_PRIORITY","priority":"P3","reason":"Không có dấu hiệu nguy hiểm trực tiếp sau khi xác minh"} | H7: 1. POST hạ mức emergency-review; 2. Kiểm tra priority P3; 3. Tiếp tục luồng bình thường | I7: 200 | J7: Phản hồi: data priority=P3 or effective priority below P5 | Cơ sở dữ liệu: Mức ưu tiên override/review decision saved; grouping/duplicate flow resumes | Tác động phụ: Audit được tạo | K7: Ticket 6640679a-b487-4eb0-8030-53b73180a91f P5/PENDING được hạ mức qua HTTP 200. DB run 1 lưu DOWNGRADED/DOWNGRADE_PRIORITY/effective_priority=P3; pipeline tiếp tục tạo run 2 SUCCEEDED/NOT_REQUIRED/P3 và classification=RESOLVED. | L7: PASS
A8: TC-P5-005 | B8: 04 Chuyển trạng thái | C8: POST /api/v1/coordinator/tickets/{ticket_id}/assign | D8: Từ chối mọi attempt phân công thủ công cho P5 đã xác nhận | E8: P0 | F8: Mức ưu tiên của ticket là P5 và emergency review gần nhất là CONFIRMED | G8: Vai trò: COORDINATOR | Path: ticket_id={{CONFIRMED_P5_TICKET_ID}} | Body: KTV_id={{TECHNICIAN_ID}} | H8: 1. POST phân công thủ công cho P5 đã xác nhận; 2. Kiểm tra response; 3. Query ticket_phân côngs for ticket | I8: 409 | J8: Phản hồi HTTP: error.code=EMERGENCY_MANUAL_ONLY. Cơ sở dữ liệu: no phân công row is được tạo; P5 remains handled manually by BQL. | K8: Gán thủ công ticket P5 trả HTTP 500, error.code=INTERNAL_ERROR; assignment_count trước/sau=0/0. | L8: FAIL | M8: BUG-P5-003 - API gán P5 không trả 409 EMERGENCY_MANUAL_ONLY dù DB không tạo assignment.
A9: TC-TECH-007 | B9: 04 Chuyển trạng thái | C9: POST /api/v1/technician/assignments/{assignment_id}/start | D9: KTV bắt đầu phân công đứng đầu hàng đợi | E9: P1 | F9: Assignment thuộc KTV; status ASSIGNED; planned_order=0; ticket APPROVED | G9: Vai trò: TECHNICIAN | Tham số đường dẫn: phân công_id={{ASSIGNMENT_ID}} | H9: 1. POST start; 2. Kiểm tra IN_PROGRESS | I9: 200 | J9: Phản hồi: data.status=IN_PROGRESS | Cơ sở dữ liệu: Assignment started_at/status được cập nhật; queue reindexed | Tác động phụ: BQL/cư dân notification nếu đã triển khai | K9: Assignment 2642bb62-9b56-4cd6-8604-25d8bfc823ed xuất hiện trong queue; POST start HTTP 200. API/DB assignment=IN_PROGRESS/IN_PROGRESS, ticket=IN_PROGRESS, started_at tồn tại=True. | L9: PASS
A10: TC-TECH-014 | B10: 04 Chuyển trạng thái | C10: POST /api/v1/technician/assignments/{assignment_id}/complete | D10: KTV hoàn thành phân công với bằng chứng | E10: P1 | F10: Assignment IN_PROGRESS; có upload_id bằng chứng hoàn thành hợp lệ và object đã được xác minh | G10: Vai trò: TECHNICIAN | Tham số đường dẫn: phân công_id={{IN_PROGRESS_ASSIGNMENT_ID}} | Body: {"resolution_note":"Đã thay khóa và kiểm tra hoạt động bình thường","evidence_upload_ids":["{{EVIDENCE_UPLOAD_ID}}"]} | H10: 1. Tạo URL tải bằng chứng hoàn thành; 2. Upload image; 3. POST complete; 4. Kiểm tra status | I10: 200 | J10: Phản hồi: data.status=COMPLETED or equivalent | Cơ sở dữ liệu: Assignment completed; ticket resolved/completed; evidence attachment saved; upload session consumed | Tác động phụ: Cư dân/BQL notification; audit | K10: Signed URL HTTP 201, upload Storage HTTP 200, complete HTTP 200. API/DB assignment=COMPLETED/COMPLETED; ticket=COMPLETED; evidence 0->1; notification 5->6; audit 2->3. | L10: PASS
A11: TC-STATE-004 | B11: 04 Chuyển trạng thái | C11: POST /api/v1/technician/assignments/{assignment_id}/complete | D11: Từ chối hoàn thành phân công lần thứ hai | E11: P0 | F11: Assignment có status COMPLETED; ticket có status COMPLETED | G11: Vai trò: TECHNICIAN | Path: phân công_id={{COMPLETED_ASSIGNMENT_ID}} | Body: completion_note và cùng các evidence ID | H11: 1. POST complete lại; 2. Query bằng chứng hoàn thành và lịch sử trạng thái | I11: 409 | J11: Phản hồi HTTP: error.code=INVALID_STATUS_TRANSITION. Cơ sở dữ liệu: không có attachment bằng chứng trùng; không có bản ghi lịch sử COMPLETED thứ hai. | K11: Complete lần hai HTTP 409, error.code=INVALID_STATUS_TRANSITION; evidence giữ 1, lịch sử COMPLETED giữ 1. | L11: PASS
A12: TC-STATE-006 | B12: 04 Chuyển trạng thái | C12: POST /api/v1/coordinator/tickets/{ticket_id}/emergency-review | D12: Từ chối quyết định emergency review lần thứ hai sau khi P5 đã confirm/downgrade | E12: P0 | F12: Lần phân tích thành công gần nhất có emergency_review_status CONFIRMED hoặc DOWNGRADED | G12: Vai trò: COORDINATOR | Path: ticket_id={{P5_REVIEWED_TICKET_ID}} | Body: decision=CONFIRM_P5 or DOWNGRADE_PRIORITY | H12: 1. POST emergency-review lại; 2. Query ai_analysis_runs and audit logs | I12: 409 | J12: Phản hồi HTTP: error.code=INVALID_STATUS_TRANSITION because latest successful run is no longer PENDING. Cơ sở dữ liệu: quyết định khẩn cấp ban đầu được giữ nguyên; không có audit quyết định thứ hai. | K12: Quyết định P5 lần hai trả HTTP 409, error.code=INVALID_STATUS_TRANSITION; DB vẫn giữ decision=CONFIRM_P5. | L12: PASS

Sheet 05_Du_Lieu
A1: Mã test case | B1: Nhóm | C1: API | D1: Kịch bản | E1: Ưu tiên | F1: Điều kiện trước | G1: Dữ liệu test | H1: Các bước test | I1: Status mong đợi | J1: Kết quả mong đợi | K1: Kết quả thực tế | L1: Trạng thái | M1: Bug / Ghi chú
A2: TC-DB-002 | B2: 05 Dữ liệu | C2: POST /api/v1/coordinator/visual-assignment/confirm | D2: Bulk visual confirm rollback toàn bộ khi một placement không hợp lệ | E2: P0 | F2: Board có hai ticket có thể phân công; một placement dùng KTV không hợp lệ hoặc ticket đã cũ | G2: Vai trò: COORDINATOR | Body: placements=[placement hợp lệ, placement không hợp lệ] | H2: 1. Capture phân công counts for both tickets; 2. POST bulk confirm; 3. Query phân côngs and dispatch events | I2: 409 | J2: Phản hồi HTTP: error.code=VISUAL_PLACEMENT_INVALID or VISUAL_UNIT_NOT_PLACEABLE. Cơ sở dữ liệu: no tạo phân công for the valid placement either; board can be refreshed safely. | K2: Visual confirm gồm một placement hợp lệ và một KTV không tồn tại trả HTTP 409, error.code=VISUAL_PLACEMENT_INVALID; assignment_count A/B=0/0. | L2: PASS
A3: TC-DB-003 | B3: 05 Dữ liệu | C3: MULTI-API | D3: Các lần enqueue trùng chỉ giữ một dispatch event đang mở cho mỗi ticket | E3: P0 | F3: Tự phân công đang bật; one approved resolved non-P5 ticket has no active phân công | G3: Vai trò: COORDINATOR | Ticket: {{APPROVED_RESOLVED_NON_P5_TICKET_ID}} | Action sources: approve/backlog/worker retry | H3: 1. Kích hoạt enqueue từ hai luồng hoặc retry nhanh; 2. GET /api/v1/BQL/dispatch/events; 3. Query dispatch_events where ticket_id and is_open=true | I3: 200 | J3: Phản hồi HTTP: một event mở hiển thị. Cơ sở dữ liệu: ràng buộc unique một phần chỉ cho phép đúng một dispatch_event đang mở cho ticket; request trùng trả về/tái sử dụng event hiện có. | K3: Hai lần enqueue trả cùng event_id=f976acc5-1eee-4e25-90bb-3c7b73fec29a; DB open_event_count=1; GET dispatch/events HTTP 200 hiển thị 1 event cho ticket. | L3: PASS
A4: TC-DB-004 | B4: 05 Dữ liệu | C4: MULTI-API | D4: Ticket status, phân công status và lịch sử nhất quán từ assign tới complete | E4: P1 | F4: Duyệtd non-P5 ticket; eligible KTV; có upload session bằng chứng hoàn thành | G4: Chuỗi vai trò: COORDINATOR sau đó TECHNICIAN | Ticket={{APPROVED_TICKET_ID}}, KTV={{TECHNICIAN_ID}} | H4: 1. BQL assigns ticket; 2. KTV bắt đầu xử lý phân công; 3. KTV completes with evidence; 4. Query ticket, phân công, ticket_status_history | I4: 200 | J4: Phản hồi HTTP: final ticket status COMPLETED and phân công status COMPLETED. Cơ sở dữ liệu: status history contains APPROVED->IN_PROGRESS->COMPLETED order; phân công completed_at tồn tại; no active phân công remains. | K4: Ticket 344a1c11-cfc6-4eae-b804-ecc83cbebbc4: APPROVED -> IN_PROGRESS -> COMPLETED; assignment 2642bb62-9b56-4cd6-8604-25d8bfc823ed: ASSIGNED -> IN_PROGRESS -> COMPLETED, completed_at tồn tại và is_active=False. | L4: PASS
A5: TC-ACCOUNT-011 | B5: 05 Dữ liệu | C5: DELETE /api/v1/coordinator/accounts/technicians/{user_id} | D5: Từ chối xóa KTV đã có lịch sử phân công | E5: P1 | F5: KTV has phân công history | G5: Vai trò: COORDINATOR | Tham số đường dẫn: user_id={{TECHNICIAN_USER_ID}} | H5: 1. DELETE KTV có lịch sử; 2. Kiểm tra bị chặn | I5: 409 | J5: Phản hồi: error.code=VALIDATION_ERROR or business conflict | Cơ sở dữ liệu: KTV remains active/existing | Tác động phụ: No auth delete | K5: DELETE KTV có lịch sử assignment trả HTTP 409, error.code=VALIDATION_ERROR; technician profile vẫn tồn tại và active=True. | L5: PASS

Sheet 06_Tich_Hop
A1: Mã test case | B1: Nhóm | C1: API | D1: Kịch bản | E1: Ưu tiên | F1: Điều kiện trước | G1: Dữ liệu test | H1: Các bước test | I1: Status mong đợi | J1: Kết quả mong đợi | K1: Kết quả thực tế | L1: Trạng thái | M1: Bug / Ghi chú
A2: TC-STORAGE-007 | B2: 06 Tích hợp | C2: POST /api/v1/storage/ticket-attachments/upload-url | D2: Storage chưa cấu hình | E2: P1 | F2: Chạy backend với cấu hình storage bị thiếu trong môi trường test | G2: Vai trò: RESIDENT | Body: {"original_filename":"incident-test.jpg","mime_type":"image/jpeg","file_size":245760} | H2: 1. Tắt cấu hình storage trong môi trường test; 2. POST upload-url; 3. Kiểm tra lỗi dịch vụ | I2: 503 | J2: Phản hồi: error.code=STORAGE_NOT_CONFIGURED | Cơ sở dữ liệu: No committed upload session if URL cannot be được tạo | Tác động phụ: Không tạo signed URL | K2: API phụ khởi động với SUPABASE_STORAGE_BUCKET rỗng; POST upload-url trả HTTP 503, error.code=STORAGE_NOT_CONFIGURED. | L2: PASS
A3: TC-INT-001 | B3: 06 Tích hợp | C3: POST /api/v1/coordinator/accounts/residents | D3: Supabase Auth unavailable khi tạo resident | E3: P1 | F3: Dùng staging/local với Supabase Admin được mock timeout hoặc bỏ cấu hình Supabase Admin; không dùng production | G3: Vai trò: COORDINATOR | Body: valid cư dân account payload | Lỗi giả lập: Supabase Admin unavailable or not configured | H3: 1. Configure auth provider failure; 2. POST tạo cư dân; 3. Query user_profiles/cư dân_profiles | I3: 503 | J3: Phản hồi HTTP: error.code=AUTH_SERVICE_UNAVAILABLE. Cơ sở dữ liệu: no partial user_profile or cư dân_profile row. Tác động phụ: no orphan auth user if auth id was được tạo before DB failure. | K3: POST tạo cư dân khi tắt Supabase Auth admin trả HTTP 503, code=AUTH_SERVICE_UNAVAILABLE; user_profiles 30->30, resident_profiles 20->20. | L3: PASS
A4: TC-INT-003 | B4: 06 Tích hợp | C4: POST /api/v1/tickets | D4: Tạo ticket từ chối upload session có object thiếu trong Storage | E4: P0 | F4: Cư dân có upload session mới nhưng endpoint thông tin object trả về 404 | G4: Vai trò: RESIDENT | Body: location_id={{LOCATION_ID}}, description="Missing object", attachment_upload_ids=[{{UPLOAD_SESSION_ID}}] | H4: 1. Tạo upload URL; 2. Không tải file lên hoặc mock thông tin object trả 404; 3. POST create ticket; 4. Query tickets/attachments/upload_sessions | I4: 400 | J4: Phản hồi HTTP: error.code=INVALID_ATTACHMENT. Cơ sở dữ liệu: no ticket and no attachment được tạo; upload session remains reusable/unconsumed according to current transaction. | K4: Fresh resident tạo signed upload HTTP 201 nhưng không PUT object; POST ticket trả HTTP 503, error.code=STORAGE_NOT_CONFIGURED; ticket_count 0->0; upload_session=pending. | L4: FAIL | M4: BUG-INT-001 - Object thiếu bị map sai lỗi hoặc transaction không rollback.
A5: TC-INT-004 | B5: 06 Tích hợp | C5: MULTI-API | D5: Lỗi LLM/agent không publish classification hoặc dispatch phân công dang dở | E5: P0 | F5: Agent service can be forced to fail or timeout in local/staging; auto phân công may be enabled | G5: Vai trò: RESIDENT sau đó COORDINATOR | Flow: tạo ticket kích hoạt lỗi phân tích | H5: 1. Tạo ticket; 2. Ép LLM hoặc agent phát sinh exception; 3. Kiểm tra khả năng hiển thị ở BQL và ai_analysis_runs; 4. Check dispatch_events | I5: N/A | J5: Cơ sở dữ liệu: latest ai_analysis_runs.status=FAILED; ticket is not auto-approved or dispatched from partial data; BQL can see retry path nếu đã triển khai by current UI/API. | K5: LLM timeout tạo session=FAILED, run=FAILED, error_code=RuntimeError; ticket=NEW/MANUAL_REVIEW; dispatch=0, assignment=0; BQL GET ticket HTTP 200. | L5: PASS
A6: TC-COORD-015 | B6: 06 Tích hợp | C6: POST /api/v1/coordinator/tickets/{ticket_id}/analysis/retry | D6: Retry analysis thất bại | E6: P1 | F6: Ticket có trạng thái phân tích failed/đủ điều kiện retry | G6: Vai trò: COORDINATOR | Tham số đường dẫn: ticket_id={{FAILED_ANALYSIS_TICKET_ID}} | H6: 1. POST analysis retry; 2. Kiểm tra lần chạy mới đã được lên lịch | I6: 202 | J6: Phản hồi: data/message indicates retry accepted | Cơ sở dữ liệu: New AIAnalysisRun/session được tạo or scheduled | Tác động phụ: Background analysis được đưa vào hàng đợi | K6: POST analysis/retry trả HTTP 200 (workbook mong đợi 202); AIAnalysisRun count 1->2; run mới status=SUCCEEDED, error_code=None. | L6: FAIL | M6: BUG-INT-003 - Retry được lên lịch nhưng endpoint trả 200 thay vì HTTP 202 theo test contract.

Sheet 07_Bao_Mat
A1: Mã test case | B1: Nhóm | C1: API | D1: Kịch bản | E1: Ưu tiên | F1: Điều kiện trước | G1: Dữ liệu test | H1: Các bước test | I1: Status mong đợi | J1: Kết quả mong đợi | K1: Kết quả thực tế | L1: Trạng thái | M1: Bug / Ghi chú
A2: TC-SEC-003 | B2: 07 Bảo mật | C2: POST /api/v1/storage/ticket-attachments/upload-url | D2: Path traversal trong filename khi upload | E2: P0 | F2: Cư dân đang active | G2: Vai trò: RESIDENT | Body: {"original_filename":"../secret.jpg","mime_type":"image/jpeg","file_size":1000} | H2: 1. POST upload-url với filename có path traversal; 2. Kiểm tra bị từ chối hoặc tạo đường dẫn đã chuẩn hóa an toàn | I2: 400 | J2: Phản hồi: error.code=INVALID_ATTACHMENT or generated storage path has no traversal | Cơ sở dữ liệu: No unsafe session/path committed | Tác động phụ: No unsafe signed URL | K2: Path traversal upload-url trả về HTTP 400; error.code=INVALID_ATTACHMENT; upload_session_count 2->2. | L2: PASS
A3: TC-SEC-004 | B3: 07 Bảo mật | C3: GET /api/v1/tickets/{ticket_id} | D3: Resident IDOR khi xem ticket | E3: P0 | F3: Ticket belongs to another unit | G3: Vai trò: RESIDENT_OTHER | Tham số đường dẫn: ticket_id={{TICKET_ID}} | H3: 1. GET ticket của user khác; 2. Kiểm tra không thể truy cập | I3: 404 | J3: Phản hồi: No ticket data leaked | K3: Resident B (unit 1002) GET ticket 48e11473-e1ab-4ad5-9577-8dea2bfa4b11 của resident A trả HTTP 404, error.code=TICKET_NOT_FOUND; response không có ticket data. | L3: PASS
A4: TC-SEC-005 | B4: 07 Bảo mật | C4: GET /api/v1/technician/assignments/{assignment_id} | D4: Technician IDOR khi xem phân công | E4: P0 | F4: Assignment belongs to another KTV | G4: Vai trò: TECHNICIAN | Tham số đường dẫn: phân công_id={{OTHER_ASSIGNMENT_ID}} | H4: 1. GET other KTV phân công; 2. Kiểm tra không thể truy cập | I4: 404 | J4: Phản hồi: No phân công data leaked | K4: KTV development GET assignment 06f29783-2bab-4d47-a99c-846dc20beb4a thuộc KTV khác trả HTTP 404, error.code=ASSIGNMENT_NOT_FOUND; không có assignment data. | L4: PASS
A5: TC-SEC-006 | B5: 07 Bảo mật | C5: POST /api/v1/tickets | D5: Field mass phân công bị bỏ qua hoặc từ chối | E5: P1 | F5: Cư dân đang active and bound | G5: Vai trò: RESIDENT | Body: {"location_id":"{{LOCATION_ID}}","description":"Test mass phân công","status":"APPROVED","được tạo_by_id":"{{OTHER_USER_ID}}"} | H5: 1. POST body có field thừa; 2. Kiểm tra bị từ chối do additionalProperties=false | I5: 422 | J5: Phản hồi: error.code=VALIDATION_ERROR | Cơ sở dữ liệu: No ticket được tạo with injected status/owner | Tác động phụ: No analysis được đưa vào hàng đợi if rejected | K5: Mass-phân công POST /tickets trả về HTTP 422; error.code=VALIDATION_ERROR; tickets_count 15->15. | L5: PASS
A6: TC-SEC-008 | B6: 07 Bảo mật | C6: GET /api/v1/coordinator/tickets/{ticket_id} | D6: Lỗi 500 không leak secret | E6: P1 | F6: Dùng môi trường test với dependency được mock để phát sinh exception ngoài dự kiến | G6: Vai trò: COORDINATOR | Tham số đường dẫn: ticket_id={{TICKET_ID}} | H6: 1. Tạm thời kích hoạt mock exception an toàn ở staging/local; 2. Gửi request; 3. Kiểm tra response/log | I6: 500 | J6: Phản hồi: error.code=INTERNAL_ERROR; no stack trace/token/secret in response | Cơ sở dữ liệu: Transaction rolled back | Tác động phụ: Request id logged | K6: Kích hoạt lỗi 500 qua assign P5: HTTP 500, error.code=INTERNAL_ERROR, request_id tồn tại=True, leak_markers=[], assignment_count 0->0. | L6: PASS
A7: TC-SEC-013 | B7: 07 Bảo mật | C7: POST /api/v1/tickets | D7: Từ chối upload session thuộc resident khác | E7: P0 | F7: Cư dân A has upload session; Cư dân B has active unit | G7: Vai trò: RESIDENT_B | Body: location_id={{LOCATION_ID}}, description="Foreign upload", attachment_upload_ids=[{{RESIDENT_A_UPLOAD_SESSION_ID}}] | H7: 1. Cư dân A requests upload URL; 2. Cư dân B posts ticket using A upload_session_id; 3. Query tickets and attachments | I7: 400 | J7: Phản hồi HTTP: error.code=INVALID_ATTACHMENT. Cơ sở dữ liệu: không có attachment ticket nào được liên kết với B; upload session của A không bị B sử dụng. | K7: Resident A tạo upload session HTTP 201; Resident B dùng upload_id đó tạo ticket trả HTTP 400, error.code=INVALID_ATTACHMENT; ticket_count B 0->0; session A=pending. | L7: PASS

Sheet 08_Dong_Thoi
A1: Mã test case | B1: Nhóm | C1: API | D1: Kịch bản | E1: Ưu tiên | F1: Điều kiện trước | G1: Dữ liệu test | H1: Các bước test | I1: Status mong đợi | J1: Kết quả mong đợi | K1: Kết quả thực tế | L1: Trạng thái | M1: Bug / Ghi chú
A2: TC-CONC-001 | B2: 08 Đồng thời | C2: POST /api/v1/coordinator/tickets/{ticket_id}/assign | D2: Hai BQL assign cùng một ticket cùng lúc | E2: P0 | F2: Duyệtd resolved non-P5 ticket with no active phân công; two eligible KTVs or same KTV available | G2: Vai trò: COORDINATOR x2 | Path: ticket_id={{APPROVED_TICKET_ID}} | Body A: KTV_id={{TECHNICIAN_A_ID}} | Body B: KTV_id={{TECHNICIAN_B_ID}} | H2: 1. Gửi hai request phân công đồng thời; 2. So sánh response; 3. Query ticket_phân côngs for các bản ghi active | I2: 200 and 409 | J2: Một request thành công. Request còn lại trả về error.code=ACTIVE_ASSIGNMENT_EXISTS or INVALID_STATUS_TRANSITION. Cơ sở dữ liệu: only one active phân công for the ticket. | K2: Hai POST assign đồng thời trả [200, 409]; loser error=['ACTIVE_ASSIGNMENT_EXISTS']; DB total_assignment=1, active_assignment=1. | L2: PASS
A3: TC-CONC-002 | B3: 08 Đồng thời | C3: MULTI-API | D3: Manual assign và visual confirm race trên cùng ticket | E3: P0 | F3: Cùng một ticket non-P5 đã duyệt xuất hiện trên visual board; form phân công thủ công cũng đang mở | G3: Vai trò: COORDINATOR x2 | API A: POST /BQL/tickets/{ticket_id}/assign | API B: POST /BQL/visual-phân công/confirm | H3: 1. Gửi đồng thời manual assign và visual confirm; 2. Làm mới board; 3. Query active phân công | I3: 200 and 409 | J3: Chỉ một luồng thành công. Luồng còn lại trả về ACTIVE_ASSIGNMENT_EXISTS, VISUAL_UNIT_NOT_PLACEABLE or VISUAL_PLACEMENT_INVALID. Cơ sở dữ liệu: one active phân công only; board no longer shows stale ticket. | K3: Board HTTP 200, unit tìm thấy=True; manual/visual race trả [200, 409]; DB total_assignment=1, active=1; board sau race còn ticket=False. | L3: PASS
A4: TC-CONC-003 | B4: 08 Đồng thời | C4: POST /api/v1/technician/assignments/{assignment_id}/start | D4: KTV double-click bắt đầu cùng phân công | E4: P1 | F4: Assignment có status ASSIGNED và ticket có status APPROVED | G4: Vai trò: TECHNICIAN | Path: phân công_id={{ASSIGNED_ASSIGNMENT_ID}} | H4: 1. Gửi hai request start đồng thời; 2. Query phân công and ticket status; 3. Check status history count | I4: 200 and 409 | J4: One request succeeds and moves phân công to IN_PROGRESS. The second returns INVALID_STATUS_TRANSITION. Cơ sở dữ liệu: chỉ ghi nhận một lần chuyển sang IN_PROGRESS. | K4: Hai POST start đồng thời trả [200, 409]; loser error=['INVALID_STATUS_TRANSITION']; DB assignment=IN_PROGRESS, số history IN_PROGRESS=1. | L4: PASS
A5: TC-CONC-004 | B5: 08 Đồng thời | C5: MULTI-API | D5: KTV cố bắt đầu hai phân công khác nhau cùng lúc | E5: P1 | F5: KTV có hai job ASSIGNED trong hàng đợi; chỉ một job được active/in progress | G5: Vai trò: TECHNICIAN | Assignment A={{ASSIGNMENT_A_ID}} | Assignment B={{ASSIGNMENT_B_ID}} | H5: 1. Gửi start requests for both phân côngs concurrently; 2. GET /api/v1/KTV/queue; 3. Query in-progress phân côngs for KTV | I5: 200 and 409 | J5: At most one phân công starts. Other request returns ASSIGNMENT_NOT_AT_QUEUE_HEAD, ACTIVE_ASSIGNMENT_EXISTS or INVALID_STATUS_TRANSITION. Cơ sở dữ liệu: KTV has no more than one IN_PROGRESS phân công. | K5: Start hai assignment khác nhau đồng thời trả [200, 409]; trạng thái DB=['IN_PROGRESS', 'ASSIGNED']; số IN_PROGRESS của KTV=1. | L5: PASS
A6: TC-CONC-005 | B6: 08 Đồng thời | C6: PUT /api/v1/coordinator/auto-assignment | D6: Hai manager cập nhật auto-phân công với cùng expected_version | E6: P1 | F6: Auto-phân công thiết lậps bản ghi tồn tại với version đã biết; có hai session BQL đang mở | G6: Vai trò: COORDINATOR x2 | Body A/B: enabled=true, acknowledged=true, expected_version={{CURRENT_VERSION}} | H6: 1. Gửi cả hai request PUT đồng thời; 2. GET thiết lập; 3. Query audit_logs for toggle action | I6: 200 and 409 | J6: Một request thành công. Request còn lại trả về error.code=CONFLICT_VERSION. Cơ sở dữ liệu: version tăng once for the winning transition; audit is not duplicated. | K6: Hai PUT expected_version=17 đồng thời trả [200, 409]; loser=['CONFLICT_VERSION']; version cuối=18; audit tăng 0. | L6: PASS
A7: TC-CONC-006 | B7: 08 Đồng thời | C7: MULTI-API | D7: Hai phân công-worker xử lý dispatch event pending mà không tạo duplicate phân công | E7: P0 | F7: Môi trường test có thể chạy hai worker; có nhiều dispatch_event pending | G7: Workers: python -m src.workers.dispatch_worker x2 | Events: {{PENDING_DISPATCH_EVENT_IDS}} | H7: 1. Bắt đầu hai worker cùng lúc; 2. Chờ một chu kỳ dispatch; 3. GET /api/v1/BQL/dispatch/events; 4. Query ticket_phân côngs | I7: N/A | J7: Each event is claimed by one worker only. Cơ sở dữ liệu: không tạo phân công trùng per ticket; events end ASSIGNED/ESCALATED/FAILED once; no stuck CLAIMED event after expiry. | K7: Hai worker đồng thời báo claimed=[3, 0]; event_statuses=['ASSIGNED', 'ASSIGNED', 'ASSIGNED']; assignment_count_per_ticket={UUID('06c9e142-b2b7-4b3e-b82b-9cb8e58ec766'): 1, UUID('a3bad828-744b-44b1-96fb-504986b1ba3b'): 1, UUID('89c3a30a-c9fe-4adf-8c5e-a895337c60fe'): 1}; stuck_claimed=0. | L7: PASS

Sheet 09_Kha_Nang_Phu_Hoi
A1: Mã test case | B1: Nhóm | C1: API | D1: Kịch bản | E1: Ưu tiên | F1: Điều kiện trước | G1: Dữ liệu test | H1: Các bước test | I1: Status mong đợi | J1: Kết quả mong đợi | K1: Kết quả thực tế | L1: Trạng thái | M1: Bug / Ghi chú
A2: TC-TICKET-007 | B2: 09 Khả năng phục hồi | C2: POST /api/v1/tickets | D2: Rate limit tạo ticket | E2: P1 | F2: Cư dân đã vượt giới hạn tạo trong cửa sổ test | G2: Vai trò: RESIDENT | Body: {"location_id":"{{LOCATION_ID}}","description":"Test spam limit"} | H2: 1. Tạo tickets đến khi đạt giới hạn; 2. Gửi thêm một request; 3. Kiểm tra giới hạn tần suất | I2: 429 | J2: Phản hồi: error.code=TICKET_CREATE_RATE_LIMITED | Cơ sở dữ liệu: No extra ticket được tạo after limit | Tác động phụ: No analysis được đưa vào hàng đợi for rejected request | K2: POST ticket sau khi resident đạt giới hạn trả HTTP 429, error.code=TICKET_CREATE_RATE_LIMITED; ticket_count 15->15; analysis_session_count 16->16. | L2: PASS
A3: TC-RES-003 | B3: 09 Khả năng phục hồi | C3: MULTI-API | D3: Worker crash sau khi claim dispatch event được phục hồi nhờ claim expiry | E3: P0 | F3: Pending dispatch_event exists; worker claim timeout can be shortened in test env | G3: Lệnh worker: python -m src.workers.dispatch_worker | Event={{PENDING_DISPATCH_EVENT_ID}} | H3: 1. Let worker claim event; 2. Kill worker before close; 3. Wait past claim_expires_at; 4. Bắt đầu worker again; 5. Inspect dispatch event | I3: N/A | J3: Cơ sở dữ liệu: expired CLAIMED event becomes PENDING and is retried or eventually FAILED after attempts. No ticket is lost and không tạo phân công trùng is được tạo. | K3: Event được seed CLAIMED hết hạn; worker report reclaimed=1; event cuối=ASSIGNED, attempt_count=2, assignment_count=1. | L3: PASS
A4: TC-RES-004 | B4: 09 Khả năng phục hồi | C4: POST /api/v1/coordinator/visual-assignment/confirm | D4: Retry visual confirm sau khi commit thành công vẫn an toàn | E4: P0 | F4: First visual confirm succeeded and ticket already has active phân công | G4: Vai trò: COORDINATOR | Body: same placements as successful request | H4: 1. Repeat same confirm request; 2. Làm mới board; 3. Query phân côngs for ticket | I4: 409 | J4: Phản hồi HTTP: error.code=VISUAL_UNIT_NOT_PLACEABLE, VISUAL_PLACEMENT_INVALID or ACTIVE_ASSIGNMENT_EXISTS. Cơ sở dữ liệu: không tạo phân công trùng; original phân công không thay đổi. | K4: Visual confirm lần đầu HTTP 200; gửi lại cùng placement HTTP 409, error.code=VISUAL_PLACEMENT_INVALID; DB total_assignment=1. | L4: PASS

Sheet 10_Hieu_Nang
A1: Mã test case | B1: Nhóm | C1: API | D1: Kịch bản | E1: Ưu tiên | F1: Điều kiện trước | G1: Dữ liệu test | H1: Các bước test | I1: Status mong đợi | J1: Kết quả mong đợi | K1: Kết quả thực tế | L1: Trạng thái | M1: Bug / Ghi chú
A2: TC-PERF-001 | B2: 10 Hiệu năng | C2: GET /api/v1/coordinator/tickets | D2: Danh sách ticket BQL dưới tải dashboard bình thường | E2: P1 | F2: Use staging-like dataset; do not run against production; use k6, Locust or JMeter | G2: Tải: 50 concurrent users | Thời lượng: 10 minutes | Query: page=1&page_size=20 with search/status filters | H2: 1. Run load script; 2. Capture p95/p99 latency and error rate; 3. Monitor DB CPU/connections | I2: N/A | J2: Acceptance Criteria: NEEDS DEFINITION. Proposed baseline only: p95 <= 1500ms, error rate < 1%, no DB connection exhaustion. | K2: BLOCKED — performance test requires staging-like load environment and acceptance criteria are NEEDS DEFINITION. Not run against current remote Supabase-backed development environment. | L2: BLOCKED | M2: Requires load environment; not executed.
A3: TC-PERF-002 | B3: 10 Hiệu năng | C3: GET /api/v1/coordinator/visual-assignment/board | D3: Board visual phân công với nhiều ticket và KTV | E3: P1 | F3: Seed 200 approved non-P5 tickets and 20 KTVs in staging-like DB | G3: Tải: 20 concurrent BQLs | Thời lượng: 10 minutes | H3: 1. Run load script against board endpoint; 2. Capture p95 and response size; 3. Kiểm tra no memory spike | I3: N/A | J3: Acceptance Criteria: NEEDS DEFINITION. Proposed baseline only: p95 <= 2000ms and board response remains consistent. | K3: BLOCKED — performance test requires staging-like load environment and acceptance criteria are NEEDS DEFINITION. Not run against current remote Supabase-backed development environment. | L3: BLOCKED | M3: Requires load environment; not executed.
A4: TC-PERF-003 | B4: 10 Hiệu năng | C4: MULTI-API | D4: Assignment worker xử lý backlog trong thời gian kỳ vọng | E4: P1 | F4: Tự phân công đang bật; seed 100 eligible dispatch events; use isolated DB | G4: Tải: 100 pending events | Thời lượng: until queue drains or 15 minutes | H4: 1. Bắt đầu phân công-worker; 2. Measure events per minute; 3. Inspect assigned/escalated/failed counts | I4: N/A | J4: Acceptance Criteria: NEEDS DEFINITION. Proposed baseline only: 100 events processed within 15 minutes with zero duplicate active phân côngs. | K4: BLOCKED — performance test requires staging-like load environment and acceptance criteria are NEEDS DEFINITION. Not run against current remote Supabase-backed development environment. | L4: BLOCKED | M4: Requires load environment; not executed.
A5: TC-PERF-004 | B5: 10 Hiệu năng | C5: POST /api/v1/tickets | D5: Burst tạo ticket cư dân vẫn ổn định | E5: P1 | F5: Use staging/local; giới hạn tần suấts accounted for; test users isolated | G5: Tải: 25 concurrent cư dâns | Thời lượng: 5 minutes | Body: valid text-only ticket | H5: 1. Run load script; 2. Track 2xx/4xx/5xx split; 3. Kiểm tra rate-limit behavior separately from server errors | I5: N/A | J5: Acceptance Criteria: NEEDS DEFINITION. Proposed baseline only: no 5xx from normal valid requests; rate-limited responses are expected only after configured limit. | K5: BLOCKED — performance test requires staging-like load environment and acceptance criteria are NEEDS DEFINITION. Not run against current remote Supabase-backed development environment. | L5: BLOCKED | M5: Requires load environment; not executed.
